Workbook
Name PlanDropdown: MEGHBELA!$A$2:$A$5

Sheet Customer Infirmation
A1: Service Type | B1: Speed Bandwith | C1: Customer Name | D1: Customer MGMT Ip | E1: Mobile Number | F1: Whatsapp Number | G1: Plan Type | H1: Validity (Days) | I1: Service Start Date | J1: Next Renewal Date | K1: Remaining days | L1: Send Alert | M1: Customer Mapping Zone | N1: Smart TV Device Name | O1: Router Brand | P1: Payment Type | Q1: Location
G2: ₹239 Plan | H2: =IF(G2="","",VLOOKUP(G2,MEGHBELA!$A$2:$C$100,3,FALSE)) -> 24 | I2: 46091 | J2: =IF(OR(I2="",H2=""),"",I2+H2) -> 46115 | K2: =IF(J2="","",J2-TODAY()) -> 26 | L2: =IF(K2="","", IF(K2<0, HYPERLINK("https://web.whatsapp.com/send?phone=91"&F2&"&text=Dear%20Customer,%20your%20internet%20plan%20expired%20on%20"&TEXT(J2,"dd-mm-yyyy")&".%20Your%20service%20is%20now%20stopped.%20Please%20renew%20immediately%20to%20restore%20service.%0A-----TRUESPEED%20BROADBAND","Send Stop Message"), IF(K2<=3, HYPERLINK("https://web.whatsapp.com/send?phone=91"&F2&"&text=Dear%20Customer,%20your%20internet%20plan%20will%20expire%20in%20"&K2&"%20days.%20Please%20renew%20before%20"&TEXT(J2,"dd-mm-yyyy")&".%0A-----TRUESPEED%20BROADBAND","Send Renewal Alert"), "")))
G3: ₹299 Plan | H3: =IF(G3="","",VLOOKUP(G3,MEGHBELA!$A$2:$C$100,3,FALSE)) -> 28 | I3: 46077 | J3: =IF(OR(I3="",H3=""),"",I3+H3) -> 46105 | K3: =IF(J3="","",J3-TODAY()) -> 16 | L3: =IF(K3="","", IF(K3<0, HYPERLINK("https://web.whatsapp.com/send?phone=91"&F3&"&text=Dear%20Customer,%20your%20internet%20plan%20expired%20on%20"&TEXT(J3,"dd-mm-yyyy")&".%20Your%20service%20is%20now%20stopped.%20Please%20renew%20immediately%20to%20restore%20service.%0A-----TRUESPEED%20BROADBAND","Send Stop Message"), IF(K3<=3, HYPERLINK("https://web.whatsapp.com/send?phone=91"&F3&"&text=Dear%20Customer,%20your%20internet%20plan%20will%20expire%20in%20"&K3&"%20days.%20Please%20renew%20before%20"&TEXT(J3,"dd-mm-yyyy")&".%0A-----TRUESPEED%20BROADBAND","Send Renewal Alert"), "")))
F4: 9749252118 | G4: ₹299 Plan | H4: =IF(G4="","",VLOOKUP(G4,MEGHBELA!$A$2:$C$100,3,FALSE)) -> 28 | I4: 46061 | J4: =IF(OR(I4="",H4=""),"",I4+H4) -> 46089 | K4: =IF(J4="","",J4-TODAY()) -> 0 | L4: =IF(K4="","", IF(K4<0, HYPERLINK("https://web.whatsapp.com/send?phone=91"&F4&"&text=Dear%20Customer,%20your%20internet%20plan%20expired%20on%20"&TEXT(J4,"dd-mm-yyyy")&".%20Your%20service%20is%20now%20stopped.%20Please%20renew%20immediately%20to%20restore%20service.%0A-----TRUESPEED%20BROADBAND","Send Stop Message"), IF(K4<=3, HYPERLINK("https://web.whatsapp.com/send?phone=91"&F4&"&text=Dear%20Customer,%20your%20internet%20plan%20will%20expire%20in%20"&K4&"%20days.%20Please%20renew%20before%20"&TEXT(J4,"dd-mm-yyyy")&".%0A-----TRUESPEED%20BROADBAND","Send Renewal Alert"), ""))) -> Send Renewal Alert
G5: ₹299 Plan | H5: =IF(G5="","",VLOOKUP(G5,MEGHBELA!$A$2:$C$100,3,FALSE)) -> 28 | I5: 46080 | J5: =IF(OR(I5="",H5=""),"",I5+H5) -> 46108 | K5: =IF(J5="","",J5-TODAY()) -> 19 | L5: =IF(K5="","", IF(K5<0, HYPERLINK("https://web.whatsapp.com/send?phone=91"&F5&"&text=Dear%20Customer,%20your%20internet%20plan%20expired%20on%20"&TEXT(J5,"dd-mm-yyyy")&".%20Your%20service%20is%20now%20stopped.%20Please%20renew%20immediately%20to%20restore%20service.%0A-----TRUESPEED%20BROADBAND","Send Stop Message"), IF(K5<=3, HYPERLINK("https://web.whatsapp.com/send?phone=91"&F5&"&text=Dear%20Customer,%20your%20internet%20plan%20will%20expire%20in%20"&K5&"%20days.%20Please%20renew%20before%20"&TEXT(J5,"dd-mm-yyyy")&".%0A-----TRUESPEED%20BROADBAND","Send Renewal Alert"), "")))
G6: ₹239 Plan | H6: =IF(G6="","",VLOOKUP(G6,MEGHBELA!$A$2:$C$100,3,FALSE)) -> 24 | I6: 46078 | J6: =IF(OR(I6="",H6=""),"",I6+H6) -> 46102 | K6: =IF(J6="","",J6-TODAY()) -> 13 | L6: =IF(K6="","", IF(K6<0, HYPERLINK("https://web.whatsapp.com/send?phone=91"&F6&"&text=Dear%20Customer,%20your%20internet%20plan%20expired%20on%20"&TEXT(J6,"dd-mm-yyyy")&".%20Your%20service%20is%20now%20stopped.%20Please%20renew%20immediately%20to%20restore%20service.%0A-----TRUESPEED%20BROADBAND","Send Stop Message"), IF(K6<=3, HYPERLINK("https://web.whatsapp.com/send?phone=91"&F6&"&text=Dear%20Customer,%20your%20internet%20plan%20will%20expire%20in%20"&K6&"%20days.%20Please%20renew%20before%20"&TEXT(J6,"dd-mm-yyyy")&".%0A-----TRUESPEED%20BROADBAND","Send Renewal Alert"), "")))
G7: ₹899 Plan | H7: =IF(G7="","",VLOOKUP(G7,MEGHBELA!$A$2:$C$100,3,FALSE)) -> 90 | I7: 46079 | J7: =IF(OR(I7="",H7=""),"",I7+H7) -> 46169 | K7: =IF(J7="","",J7-TODAY()) -> 80 | L7: =IF(K7="","", IF(K7<0, HYPERLINK("https://web.whatsapp.com/send?phone=91"&F7&"&text=Dear%20Customer,%20your%20internet%20plan%20expired%20on%20"&TEXT(J7,"dd-mm-yyyy")&".%20Your%20service%20is%20now%20stopped.%20Please%20renew%20immediately%20to%20restore%20service.%0A-----TRUESPEED%20BROADBAND","Send Stop Message"), IF(K7<=3, HYPERLINK("https://web.whatsapp.com/send?phone=91"&F7&"&text=Dear%20Customer,%20your%20internet%20plan%20will%20expire%20in%20"&K7&"%20days.%20Please%20renew%20before%20"&TEXT(J7,"dd-mm-yyyy")&".%0A-----TRUESPEED%20BROADBAND","Send Renewal Alert"), "")))
G8: ₹299 Plan | H8: =IF(G8="","",VLOOKUP(G8,MEGHBELA!$A$2:$C$100,3,FALSE)) -> 28 | I8: 46060 | J8: =IF(OR(I8="",H8=""),"",I8+H8) -> 46088 | K8: =IF(J8="","",J8-TODAY()) -> -1 | L8: =IF(K8="","", IF(K8<0, HYPERLINK("https://web.whatsapp.com/send?phone=91"&F8&"&text=Dear%20Customer,%20your%20internet%20plan%20expired%20on%20"&TEXT(J8,"dd-mm-yyyy")&".%20Your%20service%20is%20now%20stopped.%20Please%20renew%20immediately%20to%20restore%20service.%0A-----TRUESPEED%20BROADBAND","Send Stop Message"), IF(K8<=3, HYPERLINK("https://web.whatsapp.com/send?phone=91"&F8&"&text=Dear%20Customer,%20your%20internet%20plan%20will%20expire%20in%20"&K8&"%20days.%20Please%20renew%20before%20"&TEXT(J8,"dd-mm-yyyy")&".%0A-----TRUESPEED%20BROADBAND","Send Renewal Alert"), ""))) -> Send Stop Message
G9: ₹299 Plan | H9: =IF(G9="","",VLOOKUP(G9,MEGHBELA!$A$2:$C$100,3,FALSE)) -> 28 | I9: 46058 | J9: =IF(OR(I9="",H9=""),"",I9+H9) -> 46086 | K9: =IF(J9="","",J9-TODAY()) -> -3 | L9: =IF(K9="","", IF(K9<0, HYPERLINK("https://web.whatsapp.com/send?phone=91"&F9&"&text=Dear%20Customer,%20your%20internet%20plan%20expired%20on%20"&TEXT(J9,"dd-mm-yyyy")&".%20Your%20service%20is%20now%20stopped.%20Please%20renew%20immediately%20to%20restore%20service.%0A-----TRUESPEED%20BROADBAND","Send Stop Message"), IF(K9<=3, HYPERLINK("https://web.whatsapp.com/send?phone=91"&F9&"&text=Dear%20Customer,%20your%20internet%20plan%20will%20expire%20in%20"&K9&"%20days.%20Please%20renew%20before%20"&TEXT(J9,"dd-mm-yyyy")&".%0A-----TRUESPEED%20BROADBAND","Send Renewal Alert"), ""))) -> Send Stop Message
G10: ₹899 Plan | H10: =IF(G10="","",VLOOKUP(G10,MEGHBELA!$A$2:$C$100,3,FALSE)) -> 90 | I10: 45992 | J10: =IF(OR(I10="",H10=""),"",I10+H10) -> 46082 | K10: =IF(J10="","",J10-TODAY()) -> -7 | L10: =IF(K10="","", IF(K10<0, HYPERLINK("https://web.whatsapp.com/send?phone=91"&F10&"&text=Dear%20Customer,%20your%20internet%20plan%20expired%20on%20"&TEXT(J10,"dd-mm-yyyy")&".%20Your%20service%20is%20now%20stopped.%20Please%20renew%20immediately%20to%20restore%20service.%0A-----TRUESPEED%20BROADBAND","Send Stop Message"), IF(K10<=3, HYPERLINK("https://web.whatsapp.com/send?phone=91"&F10&"&text=Dear%20Customer,%20your%20internet%20plan%20will%20expire%20in%20"&K10&"%20days.%20Please%20renew%20before%20"&TEXT(J10,"dd-mm-yyyy")&".%0A-----TRUESPEED%20BROADBAND","Send Renewal Alert"), ""))) -> Send Stop Message
G11: ₹299 Plan | H11: =IF(G11="","",VLOOKUP(G11,MEGHBELA!$A$2:$C$100,3,FALSE)) -> 28 | I11: 46022 | J11: =IF(OR(I11="",H11=""),"",I11+H11) -> 46050 | K11: =IF(J11="","",J11-TODAY()) -> -39 | L11: =IF(K11="","", IF(K11<0, HYPERLINK("https://web.whatsapp.com/send?phone=91"&F11&"&text=Dear%20Customer,%20your%20internet%20plan%20expired%20on%20"&TEXT(J11,"dd-mm-yyyy")&".%20Your%20service%20is%20now%20stopped.%20Please%20renew%20immediately%20to%20restore%20service.%0A-----TRUESPEED%20BROADBAND","Send Stop Message"), IF(K11<=3, HYPERLINK("https://web.whatsapp.com/send?phone=91"&F11&"&text=Dear%20Customer,%20your%20internet%20plan%20will%20expire%20in%20"&K11&"%20days.%20Please%20renew%20before%20"&TEXT(J11,"dd-mm-yyyy")&".%0A-----TRUESPEED%20BROADBAND","Send Renewal Alert"), ""))) -> Send Stop Message
G12: ₹299 Plan | H12: =IF(G12="","",VLOOKUP(G12,MEGHBELA!$A$2:$C$100,3,FALSE)) -> 28 | I12: 46069 | J12: =IF(OR(I12="",H12=""),"",I12+H12) -> 46097 | K12: =IF(J12="","",J12-TODAY()) -> 8 | L12: =IF(K12="","", IF(K12<0, HYPERLINK("https://web.whatsapp.com/send?phone=91"&F12&"&text=Dear%20Customer,%20your%20internet%20plan%20expired%20on%20"&TEXT(J12,"dd-mm-yyyy")&".%20Your%20service%20is%20now%20stopped.%20Please%20renew%20immediately%20to%20restore%20service.%0A-----TRUESPEED%20BROADBAND","Send Stop Message"), IF(K12<=3, HYPERLINK("https://web.whatsapp.com/send?phone=91"&F12&"&text=Dear%20Customer,%20your%20internet%20plan%20will%20expire%20in%20"&K12&"%20days.%20Please%20renew%20before%20"&TEXT(J12,"dd-mm-yyyy")&".%0A-----TRUESPEED%20BROADBAND","Send Renewal Alert"), "")))
G13: ₹299 Plan | H13: =IF(G13="","",VLOOKUP(G13,MEGHBELA!$A$2:$C$100,3,FALSE)) -> 28 | I13: 46078 | J13: =IF(OR(I13="",H13=""),"",I13+H13) -> 46106 | K13: =IF(J13="","",J13-TODAY()) -> 17 | L13: =IF(K13="","", IF(K13<0, HYPERLINK("https://web.whatsapp.com/send?phone=91"&F13&"&text=Dear%20Customer,%20your%20internet%20plan%20expired%20on%20"&TEXT(J13,"dd-mm-yyyy")&".%20Your%20service%20is%20now%20stopped.%20Please%20renew%20immediately%20to%20restore%20service.%0A-----TRUESPEED%20BROADBAND","Send Stop Message"), IF(K13<=3, HYPERLINK("https://web.whatsapp.com/send?phone=91"&F13&"&text=Dear%20Customer,%20your%20internet%20plan%20will%20expire%20in%20"&K13&"%20days.%20Please%20renew%20before%20"&TEXT(J13,"dd-mm-yyyy")&".%0A-----TRUESPEED%20BROADBAND","Send Renewal Alert"), "")))
F14: 8370984399 | G14: ₹239 Plan | H14: =IF(G14="","",VLOOKUP(G14,MEGHBELA!$A$2:$C$100,3,FALSE)) -> 24 | I14: 46057 | J14: =IF(OR(I14="",H14=""),"",I14+H14) -> 46081 | K14: =IF(J14="","",J14-TODAY()) -> -8 | L14: =IF(K14="","", IF(K14<0, HYPERLINK("https://web.whatsapp.com/send?phone=91"&F14&"&text=Dear%20Customer,%20your%20internet%20plan%20expired%20on%20"&TEXT(J14,"dd-mm-yyyy")&".%20Your%20service%20is%20now%20stopped.%20Please%20renew%20immediately%20to%20restore%20service.%0A-----TRUESPEED%20BROADBAND","Send Stop Message"), IF(K14<=3, HYPERLINK("https://web.whatsapp.com/send?phone=91"&F14&"&text=Dear%20Customer,%20your%20internet%20plan%20will%20expire%20in%20"&K14&"%20days.%20Please%20renew%20before%20"&TEXT(J14,"dd-mm-yyyy")&".%0A-----TRUESPEED%20BROADBAND","Send Renewal Alert"), ""))) -> Send Stop Message
G15: ₹239 Plan | H15: =IF(G15="","",VLOOKUP(G15,MEGHBELA!$A$2:$C$100,3,FALSE)) -> 24 | I15: 46083 | J15: =IF(OR(I15="",H15=""),"",I15+H15) -> 46107 | K15: =IF(J15="","",J15-TODAY()) -> 18 | L15: =IF(K15="","", IF(K15<0, HYPERLINK("https://web.whatsapp.com/send?phone=91"&F15&"&text=Dear%20Customer,%20your%20internet%20plan%20expired%20on%20"&TEXT(J15,"dd-mm-yyyy")&".%20Your%20service%20is%20now%20stopped.%20Please%20renew%20immediately%20to%20restore%20service.%0A-----TRUESPEED%20BROADBAND","Send Stop Message"), IF(K15<=3, HYPERLINK("https://web.whatsapp.com/send?phone=91"&F15&"&text=Dear%20Customer,%20your%20internet%20plan%20will%20expire%20in%20"&K15&"%20days.%20Please%20renew%20before%20"&TEXT(J15,"dd-mm-yyyy")&".%0A-----TRUESPEED%20BROADBAND","Send Renewal Alert"), "")))
G16: ₹299 Plan | H16: =IF(G16="","",VLOOKUP(G16,MEGHBELA!$A$2:$C$100,3,FALSE)) -> 28 | I16: 46062 | J16: =IF(OR(I16="",H16=""),"",I16+H16) -> 46090 | K16: =IF(J16="","",J16-TODAY()) -> 1 | L16: =IF(K16="","", IF(K16<0, HYPERLINK("https://web.whatsapp.com/send?phone=91"&F16&"&text=Dear%20Customer,%20your%20internet%20plan%20expired%20on%20"&TEXT(J16,"dd-mm-yyyy")&".%20Your%20service%20is%20now%20stopped.%20Please%20renew%20immediately%20to%20restore%20service.%0A-----TRUESPEED%20BROADBAND","Send Stop Message"), IF(K16<=3, HYPERLINK("https://web.whatsapp.com/send?phone=91"&F16&"&text=Dear%20Customer,%20your%20internet%20plan%20will%20expire%20in%20"&K16&"%20days.%20Please%20renew%20before%20"&TEXT(J16,"dd-mm-yyyy")&".%0A-----TRUESPEED%20BROADBAND","Send Renewal Alert"), ""))) -> Send Renewal Alert
G17: ₹999 Plan | H17: =IF(G17="","",VLOOKUP(G17,MEGHBELA!$A$2:$C$100,3,FALSE)) -> 98 | I17: 46069 | J17: =IF(OR(I17="",H17=""),"",I17+H17) -> 46167 | K17: =IF(J17="","",J17-TODAY()) -> 78 | L17: =IF(K17="","", IF(K17<0, HYPERLINK("https://web.whatsapp.com/send?phone=91"&F17&"&text=Dear%20Customer,%20your%20internet%20plan%20expired%20on%20"&TEXT(J17,"dd-mm-yyyy")&".%20Your%20service%20is%20now%20stopped.%20Please%20renew%20immediately%20to%20restore%20service.%0A-----TRUESPEED%20BROADBAND","Send Stop Message"), IF(K17<=3, HYPERLINK("https://web.whatsapp.com/send?phone=91"&F17&"&text=Dear%20Customer,%20your%20internet%20plan%20will%20expire%20in%20"&K17&"%20days.%20Please%20renew%20before%20"&TEXT(J17,"dd-mm-yyyy")&".%0A-----TRUESPEED%20BROADBAND","Send Renewal Alert"), "")))
G18: ₹239 Plan | H18: =IF(G18="","",VLOOKUP(G18,MEGHBELA!$A$2:$C$100,3,FALSE)) -> 24 | I18: 46054 | J18: =IF(OR(I18="",H18=""),"",I18+H18) -> 46078 | K18: =IF(J18="","",J18-TODAY()) -> -11 | L18: =IF(K18="","", IF(K18<0, HYPERLINK("https://web.whatsapp.com/send?phone=91"&F18&"&text=Dear%20Customer,%20your%20internet%20plan%20expired%20on%20"&TEXT(J18,"dd-mm-yyyy")&".%20Your%20service%20is%20now%20stopped.%20Please%20renew%20immediately%20to%20restore%20service.%0A-----TRUESPEED%20BROADBAND","Send Stop Message"), IF(K18<=3, HYPERLINK("https://web.whatsapp.com/send?phone=91"&F18&"&text=Dear%20Customer,%20your%20internet%20plan%20will%20expire%20in%20"&K18&"%20days.%20Please%20renew%20before%20"&TEXT(J18,"dd-mm-yyyy")&".%0A-----TRUESPEED%20BROADBAND","Send Renewal Alert"), ""))) -> Send Stop Message
G19: ₹999 Plan | H19: =IF(G19="","",VLOOKUP(G19,MEGHBELA!$A$2:$C$100,3,FALSE)) -> 98 | I19: 46063 | J19: =IF(OR(I19="",H19=""),"",I19+H19) -> 46161 | K19: =IF(J19="","",J19-TODAY()) -> 72 | L19: =IF(K19="","", IF(K19<0, HYPERLINK("https://web.whatsapp.com/send?phone=91"&F19&"&text=Dear%20Customer,%20your%20internet%20plan%20expired%20on%20"&TEXT(J19,"dd-mm-yyyy")&".%20Your%20service%20is%20now%20stopped.%20Please%20renew%20immediately%20to%20restore%20service.%0A-----TRUESPEED%20BROADBAND","Send Stop Message"), IF(K19<=3, HYPERLINK("https://web.whatsapp.com/send?phone=91"&F19&"&text=Dear%20Customer,%20your%20internet%20plan%20will%20expire%20in%20"&K19&"%20days.%20Please%20renew%20before%20"&TEXT(J19,"dd-mm-yyyy")&".%0A-----TRUESPEED%20BROADBAND","Send Renewal Alert"), "")))
G20: ₹999 Plan | H20: =IF(G20="","",VLOOKUP(G20,MEGHBELA!$A$2:$C$100,3,FALSE)) -> 98 | I20: 46359 | J20: =IF(OR(I20="",H20=""),"",I20+H20) -> 46457 | K20: =IF(J20="","",J20-TODAY()) -> 368 | L20: =IF(K20="","", IF(K20<0, HYPERLINK("https://web.whatsapp.com/send?phone=91"&F20&"&text=Dear%20Customer,%20your%20internet%20plan%20expired%20on%20"&TEXT(J20,"dd-mm-yyyy")&".%20Your%20service%20is%20now%20stopped.%20Please%20renew%20immediately%20to%20restore%20service.%0A-----TRUESPEED%20BROADBAND","Send Stop Message"), IF(K20<=3, HYPERLINK("https://web.whatsapp.com/send?phone=91"&F20&"&text=Dear%20Customer,%20your%20internet%20plan%20will%20expire%20in%20"&K20&"%20days.%20Please%20renew%20before%20"&TEXT(J20,"dd-mm-yyyy")&".%0A-----TRUESPEED%20BROADBAND","Send Renewal Alert"), "")))
G21: ₹299 Plan | H21: =IF(G21="","",VLOOKUP(G21,MEGHBELA!$A$2:$C$100,3,FALSE)) -> 28 | I21: 46093 | J21: =IF(OR(I21="",H21=""),"",I21+H21) -> 46121 | K21: =IF(J21="","",J21-TODAY()) -> 32 | L21: =IF(K21="","", IF(K21<0, HYPERLINK("https://web.whatsapp.com/send?phone=91"&F21&"&text=Dear%20Customer,%20your%20internet%20plan%20expired%20on%20"&TEXT(J21,"dd-mm-yyyy")&".%20Your%20service%20is%20now%20stopped.%20Please%20renew%20immediately%20to%20restore%20service.%0A-----TRUESPEED%20BROADBAND","Send Stop Message"), IF(K21<=3, HYPERLINK("https://web.whatsapp.com/send?phone=91"&F21&"&text=Dear%20Customer,%20your%20internet%20plan%20will%20expire%20in%20"&K21&"%20days.%20Please%20renew%20before%20"&TEXT(J21,"dd-mm-yyyy")&".%0A-----TRUESPEED%20BROADBAND","Send Renewal Alert"), "")))
G22: ₹239 Plan | H22: =IF(G22="","",VLOOKUP(G22,MEGHBELA!$A$2:$C$100,3,FALSE)) -> 24 | I22: 46089 | J22: =IF(OR(I22="",H22=""),"",I22+H22) -> 46113 | K22: =IF(J22="","",J22-TODAY()) -> 24 | L22: =IF(K22="","", IF(K22<0, HYPERLINK("https://web.whatsapp.com/send?phone=91"&F22&"&text=Dear%20Customer,%20your%20internet%20plan%20expired%20on%20"&TEXT(J22,"dd-mm-yyyy")&".%20Your%20service%20is%20now%20stopped.%20Please%20renew%20immediately%20to%20restore%20service.%0A-----TRUESPEED%20BROADBAND","Send Stop Message"), IF(K22<=3, HYPERLINK("https://web.whatsapp.com/send?phone=91"&F22&"&text=Dear%20Customer,%20your%20internet%20plan%20will%20expire%20in%20"&K22&"%20days.%20Please%20renew%20before%20"&TEXT(J22,"dd-mm-yyyy")&".%0A-----TRUESPEED%20BROADBAND","Send Renewal Alert"), "")))
H23: =IF(G23="","",VLOOKUP(G23,MEGHBELA!$A$2:$C$100,3,FALSE)) | J23: =IF(OR(I23="",H23=""),"",I23+H23) | K23: =IF(J23="","",J23-TODAY()) | L23: =IF(K23="","", IF(K23<0, HYPERLINK("https://web.whatsapp.com/send?phone=91"&F23&"&text=Dear%20Customer,%20your%20internet%20plan%20expired%20on%20"&TEXT(J23,"dd-mm-yyyy")&".%20Your%20service%20is%20now%20stopped.%20Please%20renew%20immediately%20to%20restore%20service.%0A-----TRUESPEED%20BROADBAND","Send Stop Message"), IF(K23<=3, HYPERLINK("https://web.whatsapp.com/send?phone=91"&F23&"&text=Dear%20Customer,%20your%20internet%20plan%20will%20expire%20in%20"&K23&"%20days.%20Please%20renew%20before%20"&TEXT(J23,"dd-mm-yyyy")&".%0A-----TRUESPEED%20BROADBAND","Send Renewal Alert"), "")))
H24: =IF(G24="","",VLOOKUP(G24,MEGHBELA!$A$2:$C$100,3,FALSE)) | J24: =IF(OR(I24="",H24=""),"",I24+H24) | K24: =IF(J24="","",J24-TODAY()) | L24: =IF(K24="","", IF(K24<0, HYPERLINK("https://web.whatsapp.com/send?phone=91"&F24&"&text=Dear%20Customer,%20your%20internet%20plan%20expired%20on%20"&TEXT(J24,"dd-mm-yyyy")&".%20Your%20service%20is%20now%20stopped.%20Please%20renew%20immediately%20to%20restore%20service.%0A-----TRUESPEED%20BROADBAND","Send Stop Message"), IF(K24<=3, HYPERLINK("https://web.whatsapp.com/send?phone=91"&F24&"&text=Dear%20Customer,%20your%20internet%20plan%20will%20expire%20in%20"&K24&"%20days.%20Please%20renew%20before%20"&TEXT(J24,"dd-mm-yyyy")&".%0A-----TRUESPEED%20BROADBAND","Send Renewal Alert"), "")))
H25: =IF(G25="","",VLOOKUP(G25,MEGHBELA!$A$2:$C$100,3,FALSE)) | J25: =IF(OR(I25="",H25=""),"",I25+H25) | K25: =IF(J25="","",J25-TODAY()) | L25: =IF(K25="","", IF(K25<0, HYPERLINK("https://web.whatsapp.com/send?phone=91"&F25&"&text=Dear%20Customer,%20your%20internet%20plan%20expired%20on%20"&TEXT(J25,"dd-mm-yyyy")&".%20Your%20service%20is%20now%20stopped.%20Please%20renew%20immediately%20to%20restore%20service.%0A-----TRUESPEED%20BROADBAND","Send Stop Message"), IF(K25<=3, HYPERLINK("https://web.whatsapp.com/send?phone=91"&F25&"&text=Dear%20Customer,%20your%20internet%20plan%20will%20expire%20in%20"&K25&"%20days.%20Please%20renew%20before%20"&TEXT(J25,"dd-mm-yyyy")&".%0A-----TRUESPEED%20BROADBAND","Send Renewal Alert"), "")))
H26: =IF(G26="","",VLOOKUP(G26,MEGHBELA!$A$2:$C$100,3,FALSE)) | J26: =IF(OR(I26="",H26=""),"",I26+H26) | K26: =IF(J26="","",J26-TODAY()) | L26: =IF(K26="","", IF(K26<0, HYPERLINK("https://web.whatsapp.com/send?phone=91"&F26&"&text=Dear%20Customer,%20your%20internet%20plan%20expired%20on%20"&TEXT(J26,"dd-mm-yyyy")&".%20Your%20service%20is%20now%20stopped.%20Please%20renew%20immediately%20to%20restore%20service.%0A-----TRUESPEED%20BROADBAND","Send Stop Message"), IF(K26<=3, HYPERLINK("https://web.whatsapp.com/send?phone=91"&F26&"&text=Dear%20Customer,%20your%20internet%20plan%20will%20expire%20in%20"&K26&"%20days.%20Please%20renew%20before%20"&TEXT(J26,"dd-mm-yyyy")&".%0A-----TRUESPEED%20BROADBAND","Send Renewal Alert"), "")))
H27: =IF(G27="","",VLOOKUP(G27,MEGHBELA!$A$2:$C$100,3,FALSE)) | J27: =IF(OR(I27="",H27=""),"",I27+H27) | K27: =IF(J27="","",J27-TODAY()) | L27: =IF(K27="","", IF(K27<0, HYPERLINK("https://web.whatsapp.com/send?phone=91"&F27&"&text=Dear%20Customer,%20your%20internet%20plan%20expired%20on%20"&TEXT(J27,"dd-mm-yyyy")&".%20Your%20service%20is%20now%20stopped.%20Please%20renew%20immediately%20to%20restore%20service.%0A-----TRUESPEED%20BROADBAND","Send Stop Message"), IF(K27<=3, HYPERLINK("https://web.whatsapp.com/send?phone=91"&F27&"&text=Dear%20Customer,%20your%20internet%20plan%20will%20expire%20in%20"&K27&"%20days.%20Please%20renew%20before%20"&TEXT(J27,"dd-mm-yyyy")&".%0A-----TRUESPEED%20BROADBAND","Send Renewal Alert"), "")))
H28: =IF(G28="","",VLOOKUP(G28,MEGHBELA!$A$2:$C$100,3,FALSE)) | J28: =IF(OR(I28="",H28=""),"",I28+H28) | K28: =IF(J28="","",J28-TODAY()) | L28: =IF(K28="","", IF(K28<0, HYPERLINK("https://web.whatsapp.com/send?phone=91"&F28&"&text=Dear%20Customer,%20your%20internet%20plan%20expired%20on%20"&TEXT(J28,"dd-mm-yyyy")&".%20Your%20service%20is%20now%20stopped.%20Please%20renew%20immediately%20to%20restore%20service.%0A-----TRUESPEED%20BROADBAND","Send Stop Message"), IF(K28<=3, HYPERLINK("https://web.whatsapp.com/send?phone=91"&F28&"&text=Dear%20Customer,%20your%20internet%20plan%20will%20expire%20in%20"&K28&"%20days.%20Please%20renew%20before%20"&TEXT(J28,"dd-mm-yyyy")&".%0A-----TRUESPEED%20BROADBAND","Send Renewal Alert"), "")))
G29: ₹999 Plan | H29: =IF(G29="","",VLOOKUP(G29,MEGHBELA!$A$2:$C$100,3,FALSE)) -> 98 | I29: 46091 | J29: =IF(OR(I29="",H29=""),"",I29+H29) -> 46189 | K29: =IF(J29="","",J29-TODAY()) -> 100 | L29: =IF(K29="","", IF(K29<0, HYPERLINK("https://web.whatsapp.com/send?phone=91"&F29&"&text=Dear%20Customer,%20your%20internet%20plan%20expired%20on%20"&TEXT(J29,"dd-mm-yyyy")&".%20Your%20service%20is%20now%20stopped.%20Please%20renew%20immediately%20to%20restore%20service.%0A-----TRUESPEED%20BROADBAND","Send Stop Message"), IF(K29<=3, HYPERLINK("https://web.whatsapp.com/send?phone=91"&F29&"&text=Dear%20Customer,%20your%20internet%20plan%20will%20expire%20in%20"&K29&"%20days.%20Please%20renew%20before%20"&TEXT(J29,"dd-mm-yyyy")&".%0A-----TRUESPEED%20BROADBAND","Send Renewal Alert"), "")))
H30: =IF(G30="","",VLOOKUP(G30,MEGHBELA!$A$2:$C$100,3,FALSE)) | J30: =IF(OR(I30="",H30=""),"",I30+H30) | K30: =IF(J30="","",J30-TODAY()) | L30: =IF(K30="","", IF(K30<0, HYPERLINK("https://web.whatsapp.com/send?phone=91"&F30&"&text=Dear%20Customer,%20your%20internet%20plan%20expired%20on%20"&TEXT(J30,"dd-mm-yyyy")&".%20Your%20service%20is%20now%20stopped.%20Please%20renew%20immediately%20to%20restore%20service.%0A-----TRUESPEED%20BROADBAND","Send Stop Message"), IF(K30<=3, HYPERLINK("https://web.whatsapp.com/send?phone=91"&F30&"&text=Dear%20Customer,%20your%20internet%20plan%20will%20expire%20in%20"&K30&"%20days.%20Please%20renew%20before%20"&TEXT(J30,"dd-mm-yyyy")&".%0A-----TRUESPEED%20BROADBAND","Send Renewal Alert"), "")))
G31: ₹239 Plan | H31: =IF(G31="","",VLOOKUP(G31,MEGHBELA!$A$2:$C$100,3,FALSE)) -> 24 | I31: 46089 | J31: =IF(OR(I31="",H31=""),"",I31+H31) -> 46113 | K31: =IF(J31="","",J31-TODAY()) -> 24 | L31: =IF(K31="","", IF(K31<0, HYPERLINK("https://web.whatsapp.com/send?phone=91"&F31&"&text=Dear%20Customer,%20your%20internet%20plan%20expired%20on%20"&TEXT(J31,"dd-mm-yyyy")&".%20Your%20service%20is%20now%20stopped.%20Please%20renew%20immediately%20to%20restore%20service.%0A-----TRUESPEED%20BROADBAND","Send Stop Message"), IF(K31<=3, HYPERLINK("https://web.whatsapp.com/send?phone=91"&F31&"&text=Dear%20Customer,%20your%20internet%20plan%20will%20expire%20in%20"&K31&"%20days.%20Please%20renew%20before%20"&TEXT(J31,"dd-mm-yyyy")&".%0A-----TRUESPEED%20BROADBAND","Send Renewal Alert"), "")))
H32: =IF(G32="","",VLOOKUP(G32,MEGHBELA!$A$2:$C$100,3,FALSE)) | J32: =IF(OR(I32="",H32=""),"",I32+H32) | K32: =IF(J32="","",J32-TODAY()) | L32: =IF(K32="","", IF(K32<0, HYPERLINK("https://web.whatsapp.com/send?phone=91"&F32&"&text=Dear%20Customer,%20your%20internet%20plan%20expired%20on%20"&TEXT(J32,"dd-mm-yyyy")&".%20Your%20service%20is%20now%20stopped.%20Please%20renew%20immediately%20to%20restore%20service.%0A-----TRUESPEED%20BROADBAND","Send Stop Message"), IF(K32<=3, HYPERLINK("https://web.whatsapp.com/send?phone=91"&F32&"&text=Dear%20Customer,%20your%20internet%20plan%20will%20expire%20in%20"&K32&"%20days.%20Please%20renew%20before%20"&TEXT(J32,"dd-mm-yyyy")&".%0A-----TRUESPEED%20BROADBAND","Send Renewal Alert"), "")))
H33: =IF(G33="","",VLOOKUP(G33,MEGHBELA!$A$2:$C$100,3,FALSE)) | J33: =IF(OR(I33="",H33=""),"",I33+H33) | K33: =IF(J33="","",J33-TODAY()) | L33: =IF(K33="","", IF(K33<0, HYPERLINK("https://web.whatsapp.com/send?phone=91"&F33&"&text=Dear%20Customer,%20your%20internet%20plan%20expired%20on%20"&TEXT(J33,"dd-mm-yyyy")&".%20Your%20service%20is%20now%20stopped.%20Please%20renew%20immediately%20to%20restore%20service.%0A-----TRUESPEED%20BROADBAND","Send Stop Message"), IF(K33<=3, HYPERLINK("https://web.whatsapp.com/send?phone=91"&F33&"&text=Dear%20Customer,%20your%20internet%20plan%20will%20expire%20in%20"&K33&"%20days.%20Please%20renew%20before%20"&TEXT(J33,"dd-mm-yyyy")&".%0A-----TRUESPEED%20BROADBAND","Send Renewal Alert"), "")))
H34: =IF(G34="","",VLOOKUP(G34,MEGHBELA!$A$2:$C$100,3,FALSE)) | J34: =IF(OR(I34="",H34=""),"",I34+H34) | K34: =IF(J34="","",J34-TODAY()) | L34: =IF(K34="","", IF(K34<0, HYPERLINK("https://web.whatsapp.com/send?phone=91"&F34&"&text=Dear%20Customer,%20your%20internet%20plan%20expired%20on%20"&TEXT(J34,"dd-mm-yyyy")&".%20Your%20service%20is%20now%20stopped.%20Please%20renew%20immediately%20to%20restore%20service.%0A-----TRUESPEED%20BROADBAND","Send Stop Message"), IF(K34<=3, HYPERLINK("https://web.whatsapp.com/send?phone=91"&F34&"&text=Dear%20Customer,%20your%20internet%20plan%20will%20expire%20in%20"&K34&"%20days.%20Please%20renew%20before%20"&TEXT(J34,"dd-mm-yyyy")&".%0A-----TRUESPEED%20BROADBAND","Send Renewal Alert"), "")))
H35: =IF(G35="","",VLOOKUP(G35,MEGHBELA!$A$2:$C$100,3,FALSE)) | J35: =IF(OR(I35="",H35=""),"",I35+H35) | K35: =IF(J35="","",J35-TODAY()) | L35: =IF(K35="","", IF(K35<0, HYPERLINK("https://web.whatsapp.com/send?phone=91"&F35&"&text=Dear%20Customer,%20your%20internet%20plan%20expired%20on%20"&TEXT(J35,"dd-mm-yyyy")&".%20Your%20service%20is%20now%20stopped.%20Please%20renew%20immediately%20to%20restore%20service.%0A-----TRUESPEED%20BROADBAND","Send Stop Message"), IF(K35<=3, HYPERLINK("https://web.whatsapp.com/send?phone=91"&F35&"&text=Dear%20Customer,%20your%20internet%20plan%20will%20expire%20in%20"&K35&"%20days.%20Please%20renew%20before%20"&TEXT(J35,"dd-mm-yyyy")&".%0A-----TRUESPEED%20BROADBAND","Send Renewal Alert"), "")))
H36: =IF(G36="","",VLOOKUP(G36,MEGHBELA!$A$2:$C$100,3,FALSE)) | J36: =IF(OR(I36="",H36=""),"",I36+H36) | K36: =IF(J36="","",J36-TODAY()) | L36: =IF(K36="","", IF(K36<0, HYPERLINK("https://web.whatsapp.com/send?phone=91"&F36&"&text=Dear%20Customer,%20your%20internet%20plan%20expired%20on%20"&TEXT(J36,"dd-mm-yyyy")&".%20Your%20service%20is%20now%20stopped.%20Please%20renew%20immediately%20to%20restore%20service.%0A-----TRUESPEED%20BROADBAND","Send Stop Message"), IF(K36<=3, HYPERLINK("https://web.whatsapp.com/send?phone=91"&F36&"&text=Dear%20Customer,%20your%20internet%20plan%20will%20expire%20in%20"&K36&"%20days.%20Please%20renew%20before%20"&TEXT(J36,"dd-mm-yyyy")&".%0A-----TRUESPEED%20BROADBAND","Send Renewal Alert"), "")))
H37: =IF(G37="","",VLOOKUP(G37,MEGHBELA!$A$2:$C$100,3,FALSE)) | J37: =IF(OR(I37="",H37=""),"",I37+H37) | K37: =IF(J37="","",J37-TODAY()) | L37: =IF(K37="","", IF(K37<0, HYPERLINK("https://web.whatsapp.com/send?phone=91"&F37&"&text=Dear%20Customer,%20your%20internet%20plan%20expired%20on%20"&TEXT(J37,"dd-mm-yyyy")&".%20Your%20service%20is%20now%20stopped.%20Please%20renew%20immediately%20to%20restore%20service.%0A-----TRUESPEED%20BROADBAND","Send Stop Message"), IF(K37<=3, HYPERLINK("https://web.whatsapp.com/send?phone=91"&F37&"&text=Dear%20Customer,%20your%20internet%20plan%20will%20expire%20in%20"&K37&"%20days.%20Please%20renew%20before%20"&TEXT(J37,"dd-mm-yyyy")&".%0A-----TRUESPEED%20BROADBAND","Send Renewal Alert"), "")))
H38: =IF(G38="","",VLOOKUP(G38,MEGHBELA!$A$2:$C$100,3,FALSE)) | J38: =IF(OR(I38="",H38=""),"",I38+H38) | K38: =IF(J38="","",J38-TODAY()) | L38: =IF(K38="","", IF(K38<0, HYPERLINK("https://web.whatsapp.com/send?phone=91"&F38&"&text=Dear%20Customer,%20your%20internet%20plan%20expired%20on%20"&TEXT(J38,"dd-mm-yyyy")&".%20Your%20service%20is%20now%20stopped.%20Please%20renew%20immediately%20to%20restore%20service.%0A-----TRUESPEED%20BROADBAND","Send Stop Message"), IF(K38<=3, HYPERLINK("https://web.whatsapp.com/send?phone=91"&F38&"&text=Dear%20Customer,%20your%20internet%20plan%20will%20expire%20in%20"&K38&"%20days.%20Please%20renew%20before%20"&TEXT(J38,"dd-mm-yyyy")&".%0A-----TRUESPEED%20BROADBAND","Send Renewal Alert"), "")))
H39: =IF(G39="","",VLOOKUP(G39,MEGHBELA!$A$2:$C$100,3,FALSE)) | J39: =IF(OR(I39="",H39=""),"",I39+H39) | K39: =IF(J39="","",J39-TODAY()) | L39: =IF(K39="","", IF(K39<0, HYPERLINK("https://web.whatsapp.com/send?phone=91"&F39&"&text=Dear%20Customer,%20your%20internet%20plan%20expired%20on%20"&TEXT(J39,"dd-mm-yyyy")&".%20Your%20service%20is%20now%20stopped.%20Please%20renew%20immediately%20to%20restore%20service.%0A-----TRUESPEED%20BROADBAND","Send Stop Message"), IF(K39<=3, HYPERLINK("https://web.whatsapp.com/send?phone=91"&F39&"&text=Dear%20Customer,%20your%20internet%20plan%20will%20expire%20in%20"&K39&"%20days.%20Please%20renew%20before%20"&TEXT(J39,"dd-mm-yyyy")&".%0A-----TRUESPEED%20BROADBAND","Send Renewal Alert"), "")))
H40: =IF(G40="","",VLOOKUP(G40,MEGHBELA!$A$2:$C$100,3,FALSE)) | J40: =IF(OR(I40="",H40=""),"",I40+H40) | K40: =IF(J40="","",J40-TODAY()) | L40: =IF(K40="","", IF(K40<0, HYPERLINK("https://web.whatsapp.com/send?phone=91"&F40&"&text=Dear%20Customer,%20your%20internet%20plan%20expired%20on%20"&TEXT(J40,"dd-mm-yyyy")&".%20Your%20service%20is%20now%20stopped.%20Please%20renew%20immediately%20to%20restore%20service.%0A-----TRUESPEED%20BROADBAND","Send Stop Message"), IF(K40<=3, HYPERLINK("https://web.whatsapp.com/send?phone=91"&F40&"&text=Dear%20Customer,%20your%20internet%20plan%20will%20expire%20in%20"&K40&"%20days.%20Please%20renew%20before%20"&TEXT(J40,"dd-mm-yyyy")&".%0A-----TRUESPEED%20BROADBAND","Send Renewal Alert"), "")))
...

Sheet OLT or Switch MGMT Details

Sheet Expenses

Sheet MEGHBELA
A1: Plan Name | B1: Price (₹) | C1: Validity (Days) | D1: Data per Day (GB) | E1: Total Data (GB) | F1: Unlimited Calls | G1: SMS per Day | H1: Cost per Day (₹)
A2: ₹899 Plan | B2: 899 | C2: 90 | D2: 2 | E2: =C2*D2 -> 180 | F2: Yes | G2: 100 | H2: =B2/C2 -> 9.9888889
A3: ₹999 Plan | B3: 999 | C3: 98 | D3: 2 | E3: =C3*D3 -> 196 | F3: Yes | G3: 100 | H3: =B3/C3 -> 10.193878
A4: ₹299 Plan | B4: 299 | C4: 28 | D4: 5 | E4: =C4*D4 -> 140 | F4: Yes | G4: 100 | H4: =B4/C4 -> 10.678571
A5: ₹239 Plan | B5: 239 | C5: 24 | D5: 10 | E5: =C5*D5 -> 240 | F5: Yes | G5: 100 | H5: =B5/C5 -> 9.9583333
